<?xml version="1.0"?>
<robot xmlns:xacro="http://www.ros.org/wiki/xacro" >

    <xacro:include filename="inertial_macros.xacro"/>

    <material name="white">
        <color rgba="1 1 1 1" />
    </material>

    <material name="orange">
        <color rgba="1 0.3 0.1 1"/>
    </material>

    <material name="blue">
        <color rgba="0.2 0.2 1 1"/>
    </material>

    <material name="black">
        <color rgba="0 0 0 1"/>
    </material>

    <!-- BASE LINK -->

    <link name="base_link">

    </link>


    <!-- CHASSIS LINK -->

    <joint name="chassis_joint" type="fixed">
        <parent link="base_link"/>
        <child link="chassis"/>
        <!-- <origin xyz="0 0 0.07"/> -->
    </joint>

    <link name="chassis">
        <visual>
            <origin xyz="0 0 0.07"/>
            <geometry>
                <box size="0.4 0.18 0.005"/>
            </geometry>
            <material name="white"/>
        </visual>
        <collision>
            <origin xyz="0 0 0.07"/>
            <geometry>
                <box size="0.4 0.18 0.005"/>
            </geometry> 
        </collision>
        <xacro:inertial_box mass="0.5" x="0.4" y="0.18" z="0.005">
            <origin xyz="0 0 0.07" rpy="0.0 0.0 0.0"/>
        </xacro:inertial_box>
    </link>
    <gazebo reference="chassis">
        <material>Gazebo/White</material>
    </gazebo>
    
    
    <!-- LEFT FRONT WHEEL LINK -->

    <joint name="left_front_wheel_joint" type="continuous">
        <parent link="base_link"/>
        <child link="left_front_wheel"/>
        <origin xyz="0.14 0.1175 0.05" rpy="-${pi/2} 0 0" />
        <axis xyz="0 0 1"/>
    </joint>

    <link name="left_front_wheel">
        <visual>
            <geometry>
                <cylinder radius="0.05" length="0.045"/>
            </geometry>
            <material name="black"/>
        </visual>
        <collision>
            <geometry>
                <cylinder radius="0.05" length="0.045"/>
            </geometry>
        </collision>
        <xacro:inertial_cylinder mass="0.25" length="0.045" radius="0.05">
            <origin xyz="0 0 0" rpy="0.0 0.0 0.0"/>
        </xacro:inertial_cylinder>
    </link>
    <gazebo reference="left_front_wheel">
        <material>Gazebo/Black</material>
        <mu1 value="0.5"></mu1>
        <mu2 value="0.4"></mu2>
    </gazebo>
    

    <!-- LEFT REAR WHEEL LINK -->

    <joint name="left_rear_wheel_joint" type="continuous">
        <parent link="base_link"/>
        <child link="left_rear_wheel"/>
        <origin xyz="-0.14 0.1175 0.05" rpy="${pi/2} 0 0" />
        <axis xyz="0 0 -1"/>
    </joint>

    <link name="left_rear_wheel">
        <visual>
            <geometry>
                <cylinder radius="0.05" length="0.045"/>
            </geometry>
            <material name="black"/>
        </visual>
        <collision>
            <geometry>
                <cylinder radius="0.05" length="0.045"/>
            </geometry>
        </collision>
        <xacro:inertial_cylinder mass="0.25" length="0.045" radius="0.05">
            <origin xyz="0 0 0" rpy="0.0 0.0 0.0"/>
        </xacro:inertial_cylinder>
    </link>
    <gazebo reference="left_rear_wheel">
        <material>Gazebo/Black</material>
        <mu1 value="0.5"></mu1>
        <mu2 value="0.4"></mu2>
    </gazebo>
    
    <!-- RIGHT FRONT WHEEL LINK -->

    <joint name="right_front_wheel_joint" type="continuous">
        <parent link="base_link"/>
        <child link="right_front_wheel"/>
        <origin xyz="0.14 -0.1175 0.05" rpy="-${pi/2} 0 0" />
        <axis xyz="0 0 1"/>
    </joint>

    <link name="right_front_wheel">
        <visual>
            <geometry>
                <cylinder radius="0.05" length="0.045"/>
            </geometry>
            <material name="black"/>
        </visual>
        <collision>
            <geometry>
                <cylinder radius="0.05" length="0.045"/>
            </geometry>
        </collision>
        <xacro:inertial_cylinder mass="0.25" length="0.045" radius="0.05">
            <origin xyz="0 0 0" rpy="0.0 0.0 0.0"/>
        </xacro:inertial_cylinder>
    </link>
    <gazebo reference="right_front_wheel">
        <material>Gazebo/Black</material>
        <mu1 value="0.5"></mu1>
        <mu2 value="0.4"></mu2>
    </gazebo>

    <!-- RIGHT REAR WHEEL LINK -->

    <joint name="right_rear_wheel_joint" type="continuous">
        <parent link="base_link"/>
        <child link="right_rear_wheel"/>
        <origin xyz="-0.14 -0.1175 0.05" rpy="${pi/2} 0 0" />
        <axis xyz="0 0 -1"/>
    </joint>

    <link name="right_rear_wheel">
        <visual>
            <geometry>
                <cylinder radius="0.05" length="0.045"/>
            </geometry>
            <material name="black"/>
        </visual>
        <collision>
            <geometry>
                <cylinder radius="0.05" length="0.045"/>
            </geometry>
        </collision>
        <xacro:inertial_cylinder mass="0.25" length="0.045" radius="0.05">
            <origin xyz="0 0 0" rpy="0.0 0.0 0.0"/>
        </xacro:inertial_cylinder>
    </link>
    <gazebo reference="right_rear_wheel">
        <material>Gazebo/Black</material>
        <mu1 value="0.5"></mu1>
        <mu2 value="0.4"></mu2>
    </gazebo>
</robot>